Workbook

Sheet ENGATIVA
A1: MOVIL | B1: RUTERO FRONTAL | C1: RUTERO LATERAL | D1: RUTERO TRASERO | E1: COMANDO | F1: FUERA DE SERVICIO | G1: COMENTARIOS | H1: ESTADO
A2: Z10-2018 | H2: =IF(F2="Sí","FUERA DE SERVICIO",IF(AND(B2="Sí",C2="Sí",D2="Sí",E2="Sí"),"COMPLETO",IF(COUNTIF(B2:E2,"Sí")>0,"EN PROCESO","SIN REVISAR"))) -> SIN REVISAR
A3: Z10-2019 | H3: =IF(F3="Sí","FUERA DE SERVICIO",IF(AND(B3="Sí",C3="Sí",D3="Sí",E3="Sí"),"COMPLETO",IF(COUNTIF(B3:E3,"Sí")>0,"EN PROCESO","SIN REVISAR"))) -> SIN REVISAR
A4: Z10-2022 | H4: =IF(F4="Sí","FUERA DE SERVICIO",IF(AND(B4="Sí",C4="Sí",D4="Sí",E4="Sí"),"COMPLETO",IF(COUNTIF(B4:E4,"Sí")>0,"EN PROCESO","SIN REVISAR"))) -> SIN REVISAR
A5: Z10-2024 | H5: =IF(F5="Sí","FUERA DE SERVICIO",IF(AND(B5="Sí",C5="Sí",D5="Sí",E5="Sí"),"COMPLETO",IF(COUNTIF(B5:E5,"Sí")>0,"EN PROCESO","SIN REVISAR"))) -> SIN REVISAR
A6: Z10-2027 | H6: =IF(F6="Sí","FUERA DE SERVICIO",IF(AND(B6="Sí",C6="Sí",D6="Sí",E6="Sí"),"COMPLETO",IF(COUNTIF(B6:E6,"Sí")>0,"EN PROCESO","SIN REVISAR"))) -> SIN REVISAR
A7: Z10-2126 | H7: =IF(F7="Sí","FUERA DE SERVICIO",IF(AND(B7="Sí",C7="Sí",D7="Sí",E7="Sí"),"COMPLETO",IF(COUNTIF(B7:E7,"Sí")>0,"EN PROCESO","SIN REVISAR"))) -> SIN REVISAR
A8: Z10-2132 | H8: =IF(F8="Sí","FUERA DE SERVICIO",IF(AND(B8="Sí",C8="Sí",D8="Sí",E8="Sí"),"COMPLETO",IF(COUNTIF(B8:E8,"Sí")>0,"EN PROCESO","SIN REVISAR"))) -> SIN REVISAR
A9: Z10-2138 | H9: =IF(F9="Sí","FUERA DE SERVICIO",IF(AND(B9="Sí",C9="Sí",D9="Sí",E9="Sí"),"COMPLETO",IF(COUNTIF(B9:E9,"Sí")>0,"EN PROCESO","SIN REVISAR"))) -> SIN REVISAR
A10: Z10-2140 | H10: =IF(F10="Sí","FUERA DE SERVICIO",IF(AND(B10="Sí",C10="Sí",D10="Sí",E10="Sí"),"COMPLETO",IF(COUNTIF(B10:E10,"Sí")>0,"EN PROCESO","SIN REVISAR"))) -> SIN REVISAR
A11: Z10-2147 | H11: =IF(F11="Sí","FUERA DE SERVICIO",IF(AND(B11="Sí",C11="Sí",D11="Sí",E11="Sí"),"COMPLETO",IF(COUNTIF(B11:E11,"Sí")>0,"EN PROCESO","SIN REVISAR"))) -> SIN REVISAR
A12: Z10-2148 | H12: =IF(F12="Sí","FUERA DE SERVICIO",IF(AND(B12="Sí",C12="Sí",D12="Sí",E12="Sí"),"COMPLETO",IF(COUNTIF(B12:E12,"Sí")>0,"EN PROCESO","SIN REVISAR"))) -> SIN REVISAR
A13: Z10-2153 | H13: =IF(F13="Sí","FUERA DE SERVICIO",IF(AND(B13="Sí",C13="Sí",D13="Sí",E13="Sí"),"COMPLETO",IF(COUNTIF(B13:E13,"Sí")>0,"EN PROCESO","SIN REVISAR"))) -> SIN REVISAR
... A17: Z10-2163 | H17: =IF(F17="Sí","FUERA DE SERVICIO",IF(AND(B17="Sí",C17="Sí",D17="Sí",E17="Sí"),"COMPLETO",IF(COUNTIF(B17:E17,"Sí")>0,"EN PROCESO","SIN REVISAR"))) -> SIN REVISAR
A18: Z10-2165 | G18: PLACA 2 RUTERO FRONTAL PERFORADA | H18: =IF(F18="Sí","FUERA DE SERVICIO",IF(AND(B18="Sí",C18="Sí",D18="Sí",E18="Sí"),"COMPLETO",IF(COUNTIF(B18:E18,"Sí")>0,"EN PROCESO","SIN REVISAR"))) -> SIN REVISAR
A19: Z10-2166 | H19: =IF(F19="Sí","FUERA DE SERVICIO",IF(AND(B19="Sí",C19="Sí",D19="Sí",E19="Sí"),"COMPLETO",IF(COUNTIF(B19:E19,"Sí")>0,"EN PROCESO","SIN REVISAR"))) -> SIN REVISAR
A20: Z10-2169 | H20: =IF(F20="Sí","FUERA DE SERVICIO",IF(AND(B20="Sí",C20="Sí",D20="Sí",E20="Sí"),"COMPLETO",IF(COUNTIF(B20:E20,"Sí")>0,"EN PROCESO","SIN REVISAR"))) -> SIN REVISAR
A21: Z10-2175 | H21: =IF(F21="Sí","FUERA DE SERVICIO",IF(AND(B21="Sí",C21="Sí",D21="Sí",E21="Sí"),"COMPLETO",IF(COUNTIF(B21:E21,"Sí")>0,"EN PROCESO","SIN REVISAR"))) -> SIN REVISAR
A22: Z10-2182 | H22: =IF(F22="Sí","FUERA DE SERVICIO",IF(AND(B22="Sí",C22="Sí",D22="Sí",E22="Sí"),"COMPLETO",IF(COUNTIF(B22:E22,"Sí")>0,"EN PROCESO","SIN REVISAR"))) -> SIN REVISAR
A23: Z10-2187 | H23: =IF(F23="Sí","FUERA DE SERVICIO",IF(AND(B23="Sí",C23="Sí",D23="Sí",E23="Sí"),"COMPLETO",IF(COUNTIF(B23:E23,"Sí")>0,"EN PROCESO","SIN REVISAR"))) -> SIN REVISAR
A24: Z10-2188 | H24: =IF(F24="Sí","FUERA DE SERVICIO",IF(AND(B24="Sí",C24="Sí",D24="Sí",E24="Sí"),"COMPLETO",IF(COUNTIF(B24:E24,"Sí")>0,"EN PROCESO","SIN REVISAR"))) -> SIN REVISAR
A25: Z10-2189 | H25: =IF(F25="Sí","FUERA DE SERVICIO",IF(AND(B25="Sí",C25="Sí",D25="Sí",E25="Sí"),"COMPLETO",IF(COUNTIF(B25:E25,"Sí")>0,"EN PROCESO","SIN REVISAR"))) -> SIN REVISAR
A26: Z10-2190 | H26: =IF(F26="Sí","FUERA DE SERVICIO",IF(AND(B26="Sí",C26="Sí",D26="Sí",E26="Sí"),"COMPLETO",IF(COUNTIF(B26:E26,"Sí")>0,"EN PROCESO","SIN REVISAR"))) -> SIN REVISAR
A27: Z10-2196 | H27: =IF(F27="Sí","FUERA DE SERVICIO",IF(AND(B27="Sí",C27="Sí",D27="Sí",E27="Sí"),"COMPLETO",IF(COUNTIF(B27:E27,"Sí")>0,"EN PROCESO","SIN REVISAR"))) -> SIN REVISAR
A28: Z10-2197 | H28: =IF(F28="Sí","FUERA DE SERVICIO",IF(AND(B28="Sí",C28="Sí",D28="Sí",E28="Sí"),"COMPLETO",IF(COUNTIF(B28:E28,"Sí")>0,"EN PROCESO","SIN REVISAR"))) -> SIN REVISAR
A29: Z10-2211 | H29: =IF(F29="Sí","FUERA DE SERVICIO",IF(AND(B29="Sí",C29="Sí",D29="Sí",E29="Sí"),"COMPLETO",IF(COUNTIF(B29:E29,"Sí")>0,"EN PROCESO","SIN REVISAR"))) -> SIN REVISAR
A30: Z10-2212 | H30: =IF(F30="Sí","FUERA DE SERVICIO",IF(AND(B30="Sí",C30="Sí",D30="Sí",E30="Sí"),"COMPLETO",IF(COUNTIF(B30:E30,"Sí")>0,"EN PROCESO","SIN REVISAR"))) -> SIN REVISAR
... A41: Z10-2238 | H41: =IF(F41="Sí","FUERA DE SERVICIO",IF(AND(B41="Sí",C41="Sí",D41="Sí",E41="Sí"),"COMPLETO",IF(COUNTIF(B41:E41,"Sí")>0,"EN PROCESO","SIN REVISAR"))) -> SIN REVISAR
A42: Z10-2239 | G42: REVISAR RUTERO FRONTAL | H42: =IF(F42="Sí","FUERA DE SERVICIO",IF(AND(B42="Sí",C42="Sí",D42="Sí",E42="Sí"),"COMPLETO",IF(COUNTIF(B42:E42,"Sí")>0,"EN PROCESO","SIN REVISAR"))) -> SIN REVISAR
A43: Z10-2240 | H43: =IF(F43="Sí","FUERA DE SERVICIO",IF(AND(B43="Sí",C43="Sí",D43="Sí",E43="Sí"),"COMPLETO",IF(COUNTIF(B43:E43,"Sí")>0,"EN PROCESO","SIN REVISAR"))) -> SIN REVISAR
A44: Z10-2242 | H44: =IF(F44="Sí","FUERA DE SERVICIO",IF(AND(B44="Sí",C44="Sí",D44="Sí",E44="Sí"),"COMPLETO",IF(COUNTIF(B44:E44,"Sí")>0,"EN PROCESO","SIN REVISAR"))) -> SIN REVISAR
A45: Z10-2243 | H45: =IF(F45="Sí","FUERA DE SERVICIO",IF(AND(B45="Sí",C45="Sí",D45="Sí",E45="Sí"),"COMPLETO",IF(COUNTIF(B45:E45,"Sí")>0,"EN PROCESO","SIN REVISAR"))) -> SIN REVISAR
A46: Z10-2244 | H46: =IF(F46="Sí","FUERA DE SERVICIO",IF(AND(B46="Sí",C46="Sí",D46="Sí",E46="Sí"),"COMPLETO",IF(COUNTIF(B46:E46,"Sí")>0,"EN PROCESO","SIN REVISAR"))) -> SIN REVISAR
A47: Z10-2249 | H47: =IF(F47="Sí","FUERA DE SERVICIO",IF(AND(B47="Sí",C47="Sí",D47="Sí",E47="Sí"),"COMPLETO",IF(COUNTIF(B47:E47,"Sí")>0,"EN PROCESO","SIN REVISAR"))) -> SIN REVISAR
A48: Z10-2251 | H48: =IF(F48="Sí","FUERA DE SERVICIO",IF(AND(B48="Sí",C48="Sí",D48="Sí",E48="Sí"),"COMPLETO",IF(COUNTIF(B48:E48,"Sí")>0,"EN PROCESO","SIN REVISAR"))) -> SIN REVISAR
A49: Z10-2254 | H49: =IF(F49="Sí","FUERA DE SERVICIO",IF(AND(B49="Sí",C49="Sí",D49="Sí",E49="Sí"),"COMPLETO",IF(COUNTIF(B49:E49,"Sí")>0,"EN PROCESO","SIN REVISAR"))) -> SIN REVISAR
A50: Z10-2255 | H50: =IF(F50="Sí","FUERA DE SERVICIO",IF(AND(B50="Sí",C50="Sí",D50="Sí",E50="Sí"),"COMPLETO",IF(COUNTIF(B50:E50,"Sí")>0,"EN PROCESO","SIN REVISAR"))) -> SIN REVISAR
A51: Z10-2260 | H51: =IF(F51="Sí","FUERA DE SERVICIO",IF(AND(B51="Sí",C51="Sí",D51="Sí",E51="Sí"),"COMPLETO",IF(COUNTIF(B51:E51,"Sí")>0,"EN PROCESO","SIN REVISAR"))) -> SIN REVISAR
A52: Z10-2264 | G52: NO TIENE RUTERO LATERAL | H52: =IF(F52="Sí","FUERA DE SERVICIO",IF(AND(B52="Sí",C52="Sí",D52="Sí",E52="Sí"),"COMPLETO",IF(COUNTIF(B52:E52,"Sí")>0,"EN PROCESO","SIN REVISAR"))) -> SIN REVISAR
A53: Z10-2268 | H53: =IF(F53="Sí","FUERA DE SERVICIO",IF(AND(B53="Sí",C53="Sí",D53="Sí",E53="Sí"),"COMPLETO",IF(COUNTIF(B53:E53,"Sí")>0,"EN PROCESO","SIN REVISAR"))) -> SIN REVISAR
...

Sheet SUBA
A1: MOVIL | B1: RUTERO FRONTAL | C1: RUTERO LATERAL | D1: RUTERO TRASERO | E1: COMANDO | F1: FUERA DE SERVICIO | G1: COMENTARIOS | H1: ESTADO
A2: Z10-2131 | H2: =IF(F2="Sí","FUERA DE SERVICIO",IF(AND(B2="Sí",C2="Sí",D2="Sí",E2="Sí"),"COMPLETO",IF(COUNTIF(B2:E2,"Sí")>0,"EN PROCESO","SIN REVISAR"))) -> SIN REVISAR
A3: Z10-2133 | H3: =IF(F3="Sí","FUERA DE SERVICIO",IF(AND(B3="Sí",C3="Sí",D3="Sí",E3="Sí"),"COMPLETO",IF(COUNTIF(B3:E3,"Sí")>0,"EN PROCESO","SIN REVISAR"))) -> SIN REVISAR
A4: Z10-2144 | H4: =IF(F4="Sí","FUERA DE SERVICIO",IF(AND(B4="Sí",C4="Sí",D4="Sí",E4="Sí"),"COMPLETO",IF(COUNTIF(B4:E4,"Sí")>0,"EN PROCESO","SIN REVISAR"))) -> SIN REVISAR
A5: Z10-2151 | H5: =IF(F5="Sí","FUERA DE SERVICIO",IF(AND(B5="Sí",C5="Sí",D5="Sí",E5="Sí"),"COMPLETO",IF(COUNTIF(B5:E5,"Sí")>0,"EN PROCESO","SIN REVISAR"))) -> SIN REVISAR
A6: Z10-2152 | H6: =IF(F6="Sí","FUERA DE SERVICIO",IF(AND(B6="Sí",C6="Sí",D6="Sí",E6="Sí"),"COMPLETO",IF(COUNTIF(B6:E6,"Sí")>0,"EN PROCESO","SIN REVISAR"))) -> SIN REVISAR
A7: Z10-2154 | H7: =IF(F7="Sí","FUERA DE SERVICIO",IF(AND(B7="Sí",C7="Sí",D7="Sí",E7="Sí"),"COMPLETO",IF(COUNTIF(B7:E7,"Sí")>0,"EN PROCESO","SIN REVISAR"))) -> SIN REVISAR
A8: Z10-2155 | H8: =IF(F8="Sí","FUERA DE SERVICIO",IF(AND(B8="Sí",C8="Sí",D8="Sí",E8="Sí"),"COMPLETO",IF(COUNTIF(B8:E8,"Sí")>0,"EN PROCESO","SIN REVISAR"))) -> SIN REVISAR
A9: Z10-2161 | H9: =IF(F9="Sí","FUERA DE SERVICIO",IF(AND(B9="Sí",C9="Sí",D9="Sí",E9="Sí"),"COMPLETO",IF(COUNTIF(B9:E9,"Sí")>0,"EN PROCESO","SIN REVISAR"))) -> SIN REVISAR
A10: Z10-2164 | H10: =IF(F10="Sí","FUERA DE SERVICIO",IF(AND(B10="Sí",C10="Sí",D10="Sí",E10="Sí"),"COMPLETO",IF(COUNTIF(B10:E10,"Sí")>0,"EN PROCESO","SIN REVISAR"))) -> SIN REVISAR
A11: Z10-2179 | H11: =IF(F11="Sí","FUERA DE SERVICIO",IF(AND(B11="Sí",C11="Sí",D11="Sí",E11="Sí"),"COMPLETO",IF(COUNTIF(B11:E11,"Sí")>0,"EN PROCESO","SIN REVISAR"))) -> SIN REVISAR
A12: Z10-2180 | H12: =IF(F12="Sí","FUERA DE SERVICIO",IF(AND(B12="Sí",C12="Sí",D12="Sí",E12="Sí"),"COMPLETO",IF(COUNTIF(B12:E12,"Sí")>0,"EN PROCESO","SIN REVISAR"))) -> SIN REVISAR
A13: Z10-2181 | H13: =IF(F13="Sí","FUERA DE SERVICIO",IF(AND(B13="Sí",C13="Sí",D13="Sí",E13="Sí"),"COMPLETO",IF(COUNTIF(B13:E13,"Sí")>0,"EN PROCESO","SIN REVISAR"))) -> SIN REVISAR
... A129: Z10-4559 | H129: =IF(F129="Sí","FUERA DE SERVICIO",IF(AND(B129="Sí",C129="Sí",D129="Sí",E129="Sí"),"COMPLETO",IF(COUNTIF(B129:E129,"Sí")>0,"EN PROCESO","SIN REVISAR"))) -> SIN REVISAR

Sheet CONEJERA
A1: MOVIL | B1: RUTERO FRONTAL | C1: RUTERO LATERAL | D1: RUTERO TRASERO | E1: COMANDO | F1: FUERA DE SERVICIO | G1: COMENTARIOS | H1: ESTADO
A2: Z10-4134 | H2: =IF(F2="Sí","FUERA DE SERVICIO",IF(AND(B2="Sí",C2="Sí",D2="Sí",E2="Sí"),"COMPLETO",IF(COUNTIF(B2:E2,"Sí")>0,"EN PROCESO","SIN REVISAR"))) -> SIN REVISAR
A3: Z10-4159 | H3: =IF(F3="Sí","FUERA DE SERVICIO",IF(AND(B3="Sí",C3="Sí",D3="Sí",E3="Sí"),"COMPLETO",IF(COUNTIF(B3:E3,"Sí")>0,"EN PROCESO","SIN REVISAR"))) -> SIN REVISAR
A4: Z10-4203 | H4: =IF(F4="Sí","FUERA DE SERVICIO",IF(AND(B4="Sí",C4="Sí",D4="Sí",E4="Sí"),"COMPLETO",IF(COUNTIF(B4:E4,"Sí")>0,"EN PROCESO","SIN REVISAR"))) -> SIN REVISAR
A5: Z10-4209 | H5: =IF(F5="Sí","FUERA DE SERVICIO",IF(AND(B5="Sí",C5="Sí",D5="Sí",E5="Sí"),"COMPLETO",IF(COUNTIF(B5:E5,"Sí")>0,"EN PROCESO","SIN REVISAR"))) -> SIN REVISAR
A6: Z10-4237 | H6: =IF(F6="Sí","FUERA DE SERVICIO",IF(AND(B6="Sí",C6="Sí",D6="Sí",E6="Sí"),"COMPLETO",IF(COUNTIF(B6:E6,"Sí")>0,"EN PROCESO","SIN REVISAR"))) -> SIN REVISAR
A7: Z10-4253 | H7: =IF(F7="Sí","FUERA DE SERVICIO",IF(AND(B7="Sí",C7="Sí",D7="Sí",E7="Sí"),"COMPLETO",IF(COUNTIF(B7:E7,"Sí")>0,"EN PROCESO","SIN REVISAR"))) -> SIN REVISAR
A8: Z10-4254 | H8: =IF(F8="Sí","FUERA DE SERVICIO",IF(AND(B8="Sí",C8="Sí",D8="Sí",E8="Sí"),"COMPLETO",IF(COUNTIF(B8:E8,"Sí")>0,"EN PROCESO","SIN REVISAR"))) -> SIN REVISAR
A9: Z10-4263 | H9: =IF(F9="Sí","FUERA DE SERVICIO",IF(AND(B9="Sí",C9="Sí",D9="Sí",E9="Sí"),"COMPLETO",IF(COUNTIF(B9:E9,"Sí")>0,"EN PROCESO","SIN REVISAR"))) -> SIN REVISAR
A10: Z10-4267 | H10: =IF(F10="Sí","FUERA DE SERVICIO",IF(AND(B10="Sí",C10="Sí",D10="Sí",E10="Sí"),"COMPLETO",IF(COUNTIF(B10:E10,"Sí")>0,"EN PROCESO","SIN REVISAR"))) -> SIN REVISAR
A11: Z10-4269 | H11: =IF(F11="Sí","FUERA DE SERVICIO",IF(AND(B11="Sí",C11="Sí",D11="Sí",E11="Sí"),"COMPLETO",IF(COUNTIF(B11:E11,"Sí")>0,"EN PROCESO","SIN REVISAR"))) -> SIN REVISAR
A12: Z10-4274 | H12: =IF(F12="Sí","FUERA DE SERVICIO",IF(AND(B12="Sí",C12="Sí",D12="Sí",E12="Sí"),"COMPLETO",IF(COUNTIF(B12:E12,"Sí")>0,"EN PROCESO","SIN REVISAR"))) -> SIN REVISAR
A13: Z10-4276 | H13: =IF(F13="Sí","FUERA DE SERVICIO",IF(AND(B13="Sí",C13="Sí",D13="Sí",E13="Sí"),"COMPLETO",IF(COUNTIF(B13:E13,"Sí")>0,"EN PROCESO","SIN REVISAR"))) -> SIN REVISAR
... A126: Z10-4683 | H126: =IF(F126="Sí","FUERA DE SERVICIO",IF(AND(B126="Sí",C126="Sí",D126="Sí",E126="Sí"),"COMPLETO",IF(COUNTIF(B126:E126,"Sí")>0,"EN PROCESO","SIN REVISAR"))) -> SIN REVISAR

Sheet Dashboard
A1: DASHBOARD FLOTA
A3: Total móviles | B3: =SUM(B11:B13) -> 374
A4: Revisados | B4: =SUM(C11:C13) -> 0
A5: Pendientes | B5: =SUM(D11:D13) -> 374
A10: Patio | B10: Total | C10: Revisados | D10: Pendientes
A11: ENGATIVA | B11: =COUNTA(ENGATIVA!A2:A122) -> 121 | C11: =SUMPRODUCT((ENGATIVA!B2:B122="Sí")+(ENGATIVA!C2:C122="Sí")+(ENGATIVA!D2:D122="Sí")+(ENGATIVA!E2:E122="Sí")>0) -> 0 | D11: =B11-C11 -> 121
A12: SUBA | B12: =COUNTA(SUBA!A2:A129) -> 128 | C12: =SUMPRODUCT((SUBA!B2:B129="Sí")+(SUBA!C2:C129="Sí")+(SUBA!D2:D129="Sí")+(SUBA!E2:E129="Sí")>0) -> 0 | D12: =B12-C12 -> 128
A13: CONEJERA | B13: =COUNTA(CONEJERA!A2:A126) -> 125 | C13: =SUMPRODUCT((CONEJERA!B2:B126="Sí")+(CONEJERA!C2:C126="Sí")+(CONEJERA!D2:D126="Sí")+(CONEJERA!E2:E126="Sí")>0) -> 0 | D13: =B13-C13 -> 125
